2022-04-01 17:08:02,783 - instabot version: 0.117.0 (bot) - INFO - Instabot version: 0.117.0 Started
2022-04-01 17:08:02,784 - instabot version: 0.117.0 (bot) - DEBUG - Bot imported from C:\Users\harsh\AppData\Local\Programs\Python\Python310\lib\site-packages\instabot\bot\bot.py
2022-04-01 17:08:02,785 - instabot version: 0.117.0 (api_login) - INFO - Not yet logged in starting: PRE-LOGIN FLOW!
2022-04-01 17:08:14,838 - instabot version: 0.117.0 (api) - WARNING - HTTPSConnectionPool(host='i.instagram.com', port=443): Max retries exceeded with url: /api/v1/accounts/get_prefill_candidates/ (Caused by NewConnectionError('<urllib3.connection.HTTPSConnection object at 0x000002CC6D65C1F0>: Failed to establish a new connection: [Errno 11001] getaddrinfo failed'))
2022-04-01 17:08:14,855 - instabot version: 0.117.0 (api) - WARNING - HTTPSConnectionPool(host='i.instagram.com', port=443): Max retries exceeded with url: /api/v1/qe/sync/ (Caused by NewConnectionError('<urllib3.connection.HTTPSConnection object at 0x000002CC6D65C250>: Failed to establish a new connection: [Errno 11001] getaddrinfo failed'))
2022-04-01 17:08:14,858 - instabot version: 0.117.0 (api) - WARNING - HTTPSConnectionPool(host='i.instagram.com', port=443): Max retries exceeded with url: /api/v1/launcher/sync/ (Caused by NewConnectionError('<urllib3.connection.HTTPSConnection object at 0x000002CC6D65C160>: Failed to establish a new connection: [Errno 11001] getaddrinfo failed'))
2022-04-01 17:08:14,861 - instabot version: 0.117.0 (api) - WARNING - HTTPSConnectionPool(host='i.instagram.com', port=443): Max retries exceeded with url: /api/v1/accounts/contact_point_prefill/ (Caused by NewConnectionError('<urllib3.connection.HTTPSConnection object at 0x000002CC6D65C1C0>: Failed to establish a new connection: [Errno 11001] getaddrinfo failed'))
