2022-04-01 17:59:18,762 - instabot version: 0.117.0 (bot) - INFO - Instabot version: 0.117.0 Started
2022-04-01 17:59:18,764 - instabot version: 0.117.0 (bot) - DEBUG - Bot imported from C:\Users\harsh\AppData\Local\Programs\Python\Python310\lib\site-packages\instabot\bot\bot.py
2022-04-01 17:59:18,764 - instabot version: 0.117.0 (api_login) - INFO - Not yet logged in starting: PRE-LOGIN FLOW!
2022-04-01 17:59:18,773 - instabot version: 0.117.0 (api) - WARNING - HTTPSConnectionPool(host='i.instagram.com', port=443): Max retries exceeded with url: /api/v1/accounts/get_prefill_candidates/ (Caused by NewConnectionError('<urllib3.connection.HTTPSConnection object at 0x000001E044E381F0>: Failed to establish a new connection: [Errno 11001] getaddrinfo failed'))
2022-04-01 17:59:18,776 - instabot version: 0.117.0 (api) - WARNING - HTTPSConnectionPool(host='i.instagram.com', port=443): Max retries exceeded with url: /api/v1/qe/sync/ (Caused by NewConnectionError('<urllib3.connection.HTTPSConnection object at 0x000001E044E38250>: Failed to establish a new connection: [Errno 11001] getaddrinfo failed'))
2022-04-01 17:59:18,778 - instabot version: 0.117.0 (api) - WARNING - HTTPSConnectionPool(host='i.instagram.com', port=443): Max retries exceeded with url: /api/v1/launcher/sync/ (Caused by NewConnectionError('<urllib3.connection.HTTPSConnection object at 0x000001E044E38160>: Failed to establish a new connection: [Errno 11001] getaddrinfo failed'))
2022-04-01 17:59:18,780 - instabot version: 0.117.0 (api) - WARNING - HTTPSConnectionPool(host='i.instagram.com', port=443): Max retries exceeded with url: /api/v1/accounts/contact_point_prefill/ (Caused by NewConnectionError('<urllib3.connection.HTTPSConnection object at 0x000001E044E381C0>: Failed to establish a new connection: [Errno 11001] getaddrinfo failed'))
